Exception on / [GET]
Traceback (most recent call last):
  File "/usr/local/lib/python2.6/dist-packages/flask/app.py", line 1687, in wsgi_app
    response = self.full_dispatch_request()
  File "/usr/local/lib/python2.6/dist-packages/flask/app.py", line 1360, in full_dispatch_request
    rv = self.handle_user_exception(e)
  File "/usr/local/lib/python2.6/dist-packages/flask/app.py", line 1358, in full_dispatch_request
    rv = self.dispatch_request()
  File "/usr/local/lib/python2.6/dist-packages/flask/app.py", line 1344, in dispatch_request
    return self.view_functions[rule.endpoint](**req.view_args)
  File "/var/www/hickerspace.org/wsgi-scripts/restapi/auth.py", line 18, in decorated
    auth = request.authorization
NameError: global name 'request' is not defined
Exception on / [GET]
Traceback (most recent call last):
  File "/usr/local/lib/python2.6/dist-packages/flask/app.py", line 1687, in wsgi_app
    response = self.full_dispatch_request()
  File "/usr/local/lib/python2.6/dist-packages/flask/app.py", line 1360, in full_dispatch_request
    rv = self.handle_user_exception(e)
  File "/usr/local/lib/python2.6/dist-packages/flask/app.py", line 1358, in full_dispatch_request
    rv = self.dispatch_request()
  File "/usr/local/lib/python2.6/dist-packages/flask/app.py", line 1344, in dispatch_request
    return self.view_functions[rule.endpoint](**req.view_args)
  File "/var/www/hickerspace.org/wsgi-scripts/restapi/auth.py", line 18, in decorated
    auth = request.authorization
NameError: global name 'request' is not defined
Exception on / [GET]
Traceback (most recent call last):
  File "/usr/local/lib/python2.6/dist-packages/flask/app.py", line 1687, in wsgi_app
    response = self.full_dispatch_request()
  File "/usr/local/lib/python2.6/dist-packages/flask/app.py", line 1360, in full_dispatch_request
    rv = self.handle_user_exception(e)
  File "/usr/local/lib/python2.6/dist-packages/flask/app.py", line 1358, in full_dispatch_request
    rv = self.dispatch_request()
  File "/usr/local/lib/python2.6/dist-packages/flask/app.py", line 1344, in dispatch_request
    return self.view_functions[rule.endpoint](**req.view_args)
  File "/var/www/hickerspace.org/wsgi-scripts/restapi/auth.py", line 19, in decorated
    auth = request.authorization
NameError: global name 'request' is not defined
Exception on / [GET]
Traceback (most recent call last):
  File "/usr/local/lib/python2.6/dist-packages/flask/app.py", line 1687, in wsgi_app
    response = self.full_dispatch_request()
  File "/usr/local/lib/python2.6/dist-packages/flask/app.py", line 1360, in full_dispatch_request
    rv = self.handle_user_exception(e)
  File "/usr/local/lib/python2.6/dist-packages/flask/app.py", line 1358, in full_dispatch_request
    rv = self.dispatch_request()
  File "/usr/local/lib/python2.6/dist-packages/flask/app.py", line 1344, in dispatch_request
    return self.view_functions[rule.endpoint](**req.view_args)
  File "/var/www/hickerspace.org/wsgi-scripts/restapi/restapi.py", line 20, in decorated
    auth = request.authorization
NameError: global name 'request' is not defined
Exception on / [GET]
Traceback (most recent call last):
  File "/usr/local/lib/python2.6/dist-packages/flask/app.py", line 1687, in wsgi_app
    response = self.full_dispatch_request()
  File "/usr/local/lib/python2.6/dist-packages/flask/app.py", line 1360, in full_dispatch_request
    rv = self.handle_user_exception(e)
  File "/usr/local/lib/python2.6/dist-packages/flask/app.py", line 1358, in full_dispatch_request
    rv = self.dispatch_request()
  File "/usr/local/lib/python2.6/dist-packages/flask/app.py", line 1344, in dispatch_request
    return self.view_functions[rule.endpoint](**req.view_args)
  File "/var/www/hickerspace.org/wsgi-scripts/restapi/restapi.py", line 20, in decorated
    auth = request.authorization
NameError: global name 'request' is not defined
Exception on / [GET]
Traceback (most recent call last):
  File "/usr/local/lib/python2.6/dist-packages/flask/app.py", line 1687, in wsgi_app
    response = self.full_dispatch_request()
  File "/usr/local/lib/python2.6/dist-packages/flask/app.py", line 1360, in full_dispatch_request
    rv = self.handle_user_exception(e)
  File "/usr/local/lib/python2.6/dist-packages/flask/app.py", line 1358, in full_dispatch_request
    rv = self.dispatch_request()
  File "/usr/local/lib/python2.6/dist-packages/flask/app.py", line 1344, in dispatch_request
    return self.view_functions[rule.endpoint](**req.view_args)
  File "/var/www/hickerspace.org/wsgi-scripts/restapi/restapi.py", line 20, in decorated
    auth = request.authorization
NameError: global name 'request' is not defined
Exception on / [GET]
Traceback (most recent call last):
  File "/usr/local/lib/python2.6/dist-packages/flask/app.py", line 1687, in wsgi_app
    response = self.full_dispatch_request()
  File "/usr/local/lib/python2.6/dist-packages/flask/app.py", line 1360, in full_dispatch_request
    rv = self.handle_user_exception(e)
  File "/usr/local/lib/python2.6/dist-packages/flask/app.py", line 1358, in full_dispatch_request
    rv = self.dispatch_request()
  File "/usr/local/lib/python2.6/dist-packages/flask/app.py", line 1344, in dispatch_request
    return self.view_functions[rule.endpoint](**req.view_args)
  File "/var/www/hickerspace.org/wsgi-scripts/restapi/restapi.py", line 20, in decorated
    auth = request.authorization
NameError: global name 'request' is not defined
Exception on / [GET]
Traceback (most recent call last):
  File "/usr/local/lib/python2.6/dist-packages/flask/app.py", line 1687, in wsgi_app
    response = self.full_dispatch_request()
  File "/usr/local/lib/python2.6/dist-packages/flask/app.py", line 1360, in full_dispatch_request
    rv = self.handle_user_exception(e)
  File "/usr/local/lib/python2.6/dist-packages/flask/app.py", line 1358, in full_dispatch_request
    rv = self.dispatch_request()
  File "/usr/local/lib/python2.6/dist-packages/flask/app.py", line 1344, in dispatch_request
    return self.view_functions[rule.endpoint](**req.view_args)
  File "/var/www/hickerspace.org/wsgi-scripts/restapi/restapi.py", line 22, in decorated
    return authenticate()
  File "/var/www/hickerspace.org/wsgi-scripts/restapi/restapi.py", line 10, in authenticate
    resp = jsonify(message)
NameError: global name 'jsonify' is not defined
Exception on / [GET]
Traceback (most recent call last):
  File "/usr/local/lib/python2.6/dist-packages/flask/app.py", line 1687, in wsgi_app
    response = self.full_dispatch_request()
  File "/usr/local/lib/python2.6/dist-packages/flask/app.py", line 1360, in full_dispatch_request
    rv = self.handle_user_exception(e)
  File "/usr/local/lib/python2.6/dist-packages/flask/app.py", line 1358, in full_dispatch_request
    rv = self.dispatch_request()
  File "/usr/local/lib/python2.6/dist-packages/flask/app.py", line 1344, in dispatch_request
    return self.view_functions[rule.endpoint](**req.view_args)
  File "/var/www/hickerspace.org/wsgi-scripts/restapi/restapi.py", line 22, in decorated
    return authenticate()
  File "/var/www/hickerspace.org/wsgi-scripts/restapi/restapi.py", line 10, in authenticate
    resp = jsonify(message)
NameError: global name 'jsonify' is not defined
Exception on / [GET]
Traceback (most recent call last):
  File "/usr/local/lib/python2.6/dist-packages/flask/app.py", line 1687, in wsgi_app
    response = self.full_dispatch_request()
  File "/usr/local/lib/python2.6/dist-packages/flask/app.py", line 1360, in full_dispatch_request
    rv = self.handle_user_exception(e)
  File "/usr/local/lib/python2.6/dist-packages/flask/app.py", line 1358, in full_dispatch_request
    rv = self.dispatch_request()
  File "/usr/local/lib/python2.6/dist-packages/flask/app.py", line 1344, in dispatch_request
    return self.view_functions[rule.endpoint](**req.view_args)
  File "/var/www/hickerspace.org/wsgi-scripts/restapi/auth.py", line 26, in decorated
    return authenticate("Authentication Failed.")
TypeError: authenticate() takes no arguments (1 given)
Exception on / [GET]
Traceback (most recent call last):
  File "/usr/local/lib/python2.6/dist-packages/flask/app.py", line 1687, in wsgi_app
    response = self.full_dispatch_request()
  File "/usr/local/lib/python2.6/dist-packages/flask/app.py", line 1360, in full_dispatch_request
    rv = self.handle_user_exception(e)
  File "/usr/local/lib/python2.6/dist-packages/flask/app.py", line 1358, in full_dispatch_request
    rv = self.dispatch_request()
  File "/usr/local/lib/python2.6/dist-packages/flask/app.py", line 1344, in dispatch_request
    return self.view_functions[rule.endpoint](**req.view_args)
  File "/var/www/hickerspace.org/wsgi-scripts/restapi/auth.py", line 25, in decorated
    return authenticate("Authentication Failed.")
TypeError: authenticate() takes no arguments (1 given)
